<mujoco>
    <option gravity="0 0 0" />
    <worldbody>
        <light diffuse=".5 .5 .5" pos="0 0 3" dir="0 0 -1" />
        <geom type="plane" size="4 4 0.1" rgba=".5 .5 .5 1" />
        <body pos="0.5 0 0.1" euler="0 90 0">
            <joint type="hinge" axis="-1 0 0" pos="0 0 -0.5" />
            <geom type="cylinder" size=".05 .5" rgba="0.3 0.9 0.6 1"/>

            <body pos="0 0 1" euler="0 0 0">
              <joint type="hinge" axis="-1 0 0" pos="0 0 -0.5" />
              <geom type="cylinder" size=".05 .5" rgba="0.39 0.3 0.6 1"/>
              <!-- <body pos="0 0 0.5" euler="0 0 0">
                   <geom type="sphere" size=".1" rgba="0.39 0.7 0.6 1"/>
              </body> -->
              <site name="tip" size="0.1" pos="0 0 0.5" />
            </body>
           
        </body>
    </worldbody>
    <sensor>
      <framepos objtype="site" objname="tip" />
    </sensor>
</mujoco>