<mujoco>
    <option gravity="0 0 -9.8" />
    <worldbody>
        <light diffuse=".5 .5 .5" pos="0 0 3" dir="0 0 -1" />
        <geom type="plane" size="6 6 0.1" rgba=".5 .5 .5 1" />
        <body name = "chassis" pos="0 0 .2" euler="0 90 0">
            <joint type="free" />
            <site name="marker" size="0.1" pos="0 0 0" />
            <geom type="box" size=".05 .2 .5" rgba="0.3 0.9 0.6 1"/>
            <body   pos="0 0.3 -0.5" euler="90 0 0">
                <joint name = "leftwheel" type="hinge" axis="0 0 -1" />
                <geom type="cylinder" size=".2 0.05" rgba="0.4 0.9 0.4 1"/>
            </body>    
            <body  pos="0 -0.3 -0.5" euler="90 0 0">
                <joint name = "rightwheel"  type="hinge" axis="0 0 -1" />
                <geom type="cylinder" size=".2 0.05" rgba="0.4 0.9 0.4 1"/>
            </body>     
        </body>       
    </worldbody>
    <actuator>
       <velocity name="left-velociy-servo" joint="leftwheel" kv="100" />
       <velocity name="right-velociy-servo" joint="rightwheel" kv="100" />
    </actuator>
     <sensor>
      <framepos objtype="site" objname="marker" />
    </sensor>
</mujoco>