<mujoco>
    <!-- <option gravity="0 0 0" /> -->
    <asset>
         <material name="floor" texture="checks1" texrepeat="4 4"  texuniform="true" />
        <texture name="checks1" builtin="checker" type="2d" width="256" height="256" rgb1="0 0 0" rgb2="1 1 1" />
         <material name="ball" texture="checks2" texrepeat="10 10"  texuniform="true" />
        <texture name="checks2" builtin="checker" type="2d" width="256" height="256" rgb1="1 1 0" rgb2="0 0 1" />


    </asset>
    <worldbody>
        <light diffuse=".5 .5 .5" pos="0 0 3" dir="0 0 -1" />
        <geom type="plane" size="100 0.5 0.1"  material="floor" />
 

        <body pos="0 0 .1">
            <joint type="slide" axis="1 0 0" />
            <joint type="slide" axis="0 0 1" />
            <joint type="hinge" axis="0 -1 0" />
            <geom type="sphere" size=".1" rgba="0.4 0. 0.9 1"  material="ball" />

        </body>

    </worldbody>
</mujoco>